2019-12-04 19:54:22,669 ERROR: Exception on /send_message/mimi [GET] [in /home/donjoe/Desktop/projects/sched/venv/lib/python3.5/site-packages/flask/app.py:1891]
Traceback (most recent call last):
  File "/home/donjoe/Desktop/projects/sched/venv/lib/python3.5/site-packages/flask/app.py", line 2446, in wsgi_app
    response = self.full_dispatch_request()
  File "/home/donjoe/Desktop/projects/sched/venv/lib/python3.5/site-packages/flask/app.py", line 1951, in full_dispatch_request
    rv = self.handle_user_exception(e)
  File "/home/donjoe/Desktop/projects/sched/venv/lib/python3.5/site-packages/flask/app.py", line 1820, in handle_user_exception
    reraise(exc_type, exc_value, tb)
  File "/home/donjoe/Desktop/projects/sched/venv/lib/python3.5/site-packages/flask/_compat.py", line 39, in reraise
    raise value
  File "/home/donjoe/Desktop/projects/sched/venv/lib/python3.5/site-packages/flask/app.py", line 1949, in full_dispatch_request
    rv = self.dispatch_request()
  File "/home/donjoe/Desktop/projects/sched/venv/lib/python3.5/site-packages/flask/app.py", line 1935, in dispatch_request
    return self.view_functions[rule.endpoint](**req.view_args)
  File "/home/donjoe/Desktop/projects/sched/venv/lib/python3.5/site-packages/flask_login/utils.py", line 261, in decorated_view
    return func(*args, **kwargs)
  File "/home/donjoe/Desktop/projects/sched_blog/app/main/routes.py", line 182, in send_message
    return render_template('send_message.html', title='Send Message', form=form, recipient=recipient)
  File "/home/donjoe/Desktop/projects/sched/venv/lib/python3.5/site-packages/flask/templating.py", line 140, in render_template
    ctx.app,
  File "/home/donjoe/Desktop/projects/sched/venv/lib/python3.5/site-packages/flask/templating.py", line 120, in _render
    rv = template.render(context)
  File "/home/donjoe/Desktop/projects/sched/venv/lib/python3.5/site-packages/jinja2/environment.py", line 1008, in render
    return self.environment.handle_exception(exc_info, True)
  File "/home/donjoe/Desktop/projects/sched/venv/lib/python3.5/site-packages/jinja2/environment.py", line 780, in handle_exception
    reraise(exc_type, exc_value, tb)
  File "/home/donjoe/Desktop/projects/sched/venv/lib/python3.5/site-packages/jinja2/_compat.py", line 37, in reraise
    raise value.with_traceback(tb)
  File "/home/donjoe/Desktop/projects/sched_blog/app/templates/send_message.html", line 2, in top-level template code
    <!--{% import 'bootstrap/wtf.html' as wtf %}-->
  File "/home/donjoe/Desktop/projects/sched/venv/lib/python3.5/site-packages/flask/templating.py", line 60, in get_source
    return self._get_source_fast(environment, template)
  File "/home/donjoe/Desktop/projects/sched/venv/lib/python3.5/site-packages/flask/templating.py", line 89, in _get_source_fast
    raise TemplateNotFound(template)
jinja2.exceptions.TemplateNotFound: bootstrap/wtf.html
2019-12-04 19:54:26,471 ERROR: Exception on /send_message/mimi [GET] [in /home/donjoe/Desktop/projects/sched/venv/lib/python3.5/site-packages/flask/app.py:1891]
Traceback (most recent call last):
  File "/home/donjoe/Desktop/projects/sched/venv/lib/python3.5/site-packages/flask/app.py", line 2446, in wsgi_app
    response = self.full_dispatch_request()
  File "/home/donjoe/Desktop/projects/sched/venv/lib/python3.5/site-packages/flask/app.py", line 1951, in full_dispatch_request
    rv = self.handle_user_exception(e)
  File "/home/donjoe/Desktop/projects/sched/venv/lib/python3.5/site-packages/flask/app.py", line 1820, in handle_user_exception
    reraise(exc_type, exc_value, tb)
  File "/home/donjoe/Desktop/projects/sched/venv/lib/python3.5/site-packages/flask/_compat.py", line 39, in reraise
    raise value
  File "/home/donjoe/Desktop/projects/sched/venv/lib/python3.5/site-packages/flask/app.py", line 1949, in full_dispatch_request
    rv = self.dispatch_request()
  File "/home/donjoe/Desktop/projects/sched/venv/lib/python3.5/site-packages/flask/app.py", line 1935, in dispatch_request
    return self.view_functions[rule.endpoint](**req.view_args)
  File "/home/donjoe/Desktop/projects/sched/venv/lib/python3.5/site-packages/flask_login/utils.py", line 261, in decorated_view
    return func(*args, **kwargs)
  File "/home/donjoe/Desktop/projects/sched_blog/app/main/routes.py", line 182, in send_message
    return render_template('send_message.html', title='Send Message', form=form, recipient=recipient)
  File "/home/donjoe/Desktop/projects/sched/venv/lib/python3.5/site-packages/flask/templating.py", line 140, in render_template
    ctx.app,
  File "/home/donjoe/Desktop/projects/sched/venv/lib/python3.5/site-packages/flask/templating.py", line 120, in _render
    rv = template.render(context)
  File "/home/donjoe/Desktop/projects/sched/venv/lib/python3.5/site-packages/jinja2/environment.py", line 1008, in render
    return self.environment.handle_exception(exc_info, True)
  File "/home/donjoe/Desktop/projects/sched/venv/lib/python3.5/site-packages/jinja2/environment.py", line 780, in handle_exception
    reraise(exc_type, exc_value, tb)
  File "/home/donjoe/Desktop/projects/sched/venv/lib/python3.5/site-packages/jinja2/_compat.py", line 37, in reraise
    raise value.with_traceback(tb)
  File "/home/donjoe/Desktop/projects/sched_blog/app/templates/send_message.html", line 2, in top-level template code
    <!--{% import 'bootstrap/wtf.html' as wtf %}-->
  File "/home/donjoe/Desktop/projects/sched/venv/lib/python3.5/site-packages/flask/templating.py", line 60, in get_source
    return self._get_source_fast(environment, template)
  File "/home/donjoe/Desktop/projects/sched/venv/lib/python3.5/site-packages/flask/templating.py", line 89, in _get_source_fast
    raise TemplateNotFound(template)
jinja2.exceptions.TemplateNotFound: bootstrap/wtf.html
2019-12-04 19:58:18,312 INFO: Microblog startup [in /home/donjoe/Desktop/projects/sched_blog/app/__init__.py:71]
2019-12-04 19:58:18,313 INFO: Microblog startup [in /home/donjoe/Desktop/projects/sched_blog/app/__init__.py:89]
2019-12-04 19:58:18,313 INFO: Microblog startup [in /home/donjoe/Desktop/projects/sched_blog/app/__init__.py:89]
2019-12-04 19:58:26,372 ERROR: Exception on /send_message/mimi [GET] [in /home/donjoe/Desktop/projects/sched/venv/lib/python3.5/site-packages/flask/app.py:1891]
Traceback (most recent call last):
  File "/home/donjoe/Desktop/projects/sched/venv/lib/python3.5/site-packages/flask/app.py", line 2446, in wsgi_app
    response = self.full_dispatch_request()
  File "/home/donjoe/Desktop/projects/sched/venv/lib/python3.5/site-packages/flask/app.py", line 1951, in full_dispatch_request
    rv = self.handle_user_exception(e)
  File "/home/donjoe/Desktop/projects/sched/venv/lib/python3.5/site-packages/flask/app.py", line 1820, in handle_user_exception
    reraise(exc_type, exc_value, tb)
  File "/home/donjoe/Desktop/projects/sched/venv/lib/python3.5/site-packages/flask/_compat.py", line 39, in reraise
    raise value
  File "/home/donjoe/Desktop/projects/sched/venv/lib/python3.5/site-packages/flask/app.py", line 1949, in full_dispatch_request
    rv = self.dispatch_request()
  File "/home/donjoe/Desktop/projects/sched/venv/lib/python3.5/site-packages/flask/app.py", line 1935, in dispatch_request
    return self.view_functions[rule.endpoint](**req.view_args)
  File "/home/donjoe/Desktop/projects/sched/venv/lib/python3.5/site-packages/flask_login/utils.py", line 261, in decorated_view
    return func(*args, **kwargs)
  File "/home/donjoe/Desktop/projects/sched_blog/app/main/routes.py", line 182, in send_message
    return render_template('send_message.html', title='Send Message', form=form, recipient=recipient)
  File "/home/donjoe/Desktop/projects/sched/venv/lib/python3.5/site-packages/flask/templating.py", line 140, in render_template
    ctx.app,
  File "/home/donjoe/Desktop/projects/sched/venv/lib/python3.5/site-packages/flask/templating.py", line 120, in _render
    rv = template.render(context)
  File "/home/donjoe/Desktop/projects/sched/venv/lib/python3.5/site-packages/jinja2/environment.py", line 1008, in render
    return self.environment.handle_exception(exc_info, True)
  File "/home/donjoe/Desktop/projects/sched/venv/lib/python3.5/site-packages/jinja2/environment.py", line 780, in handle_exception
    reraise(exc_type, exc_value, tb)
  File "/home/donjoe/Desktop/projects/sched/venv/lib/python3.5/site-packages/jinja2/_compat.py", line 37, in reraise
    raise value.with_traceback(tb)
  File "/home/donjoe/Desktop/projects/sched_blog/app/templates/send_message.html", line 1, in top-level template code
    {% extends "base.html" %}
  File "/home/donjoe/Desktop/projects/sched_blog/app/templates/base.html", line 23, in top-level template code
    {% block content %} {% endblock %}
  File "/home/donjoe/Desktop/projects/sched_blog/app/templates/send_message.html", line 11, in block "content"
    {{ form.about_me(cols=50, rows=4) }}<br>
jinja2.exceptions.UndefinedError: 'app.main.forms.MessageForm object' has no attribute 'about_me'
